[2025-02-04T06:44:07.144+0000] {taskinstance.py:1165} INFO - Dependencies all met for <TaskInstance: user_processing.store_user manual__2025-02-04T06:43:50.293731+00:00 [queued]>
[2025-02-04T06:44:07.160+0000] {taskinstance.py:1165} INFO - Dependencies all met for <TaskInstance: user_processing.store_user manual__2025-02-04T06:43:50.293731+00:00 [queued]>
[2025-02-04T06:44:07.161+0000] {taskinstance.py:1362} INFO - 
--------------------------------------------------------------------------------
[2025-02-04T06:44:07.161+0000] {taskinstance.py:1363} INFO - Starting attempt 1 of 1
[2025-02-04T06:44:07.162+0000] {taskinstance.py:1364} INFO - 
--------------------------------------------------------------------------------
[2025-02-04T06:44:07.183+0000] {taskinstance.py:1383} INFO - Executing <Task(PythonOperator): store_user> on 2025-02-04 06:43:50.293731+00:00
[2025-02-04T06:44:07.190+0000] {standard_task_runner.py:55} INFO - Started process 7089 to run task
[2025-02-04T06:44:07.196+0000] {standard_task_runner.py:82} INFO - Running: ['***', 'tasks', 'run', 'user_processing', 'store_user', 'manual__2025-02-04T06:43:50.293731+00:00', '--job-id', '21', '--raw', '--subdir', 'DAGS_FOLDER/user_processing.py', '--cfg-path', '/tmp/tmps4phfebq']
[2025-02-04T06:44:07.200+0000] {standard_task_runner.py:83} INFO - Job 21: Subtask store_user
[2025-02-04T06:44:07.306+0000] {task_command.py:376} INFO - Running <TaskInstance: user_processing.store_user manual__2025-02-04T06:43:50.293731+00:00 [running]> on host fb1f760c5ca3
[2025-02-04T06:44:07.427+0000] {taskinstance.py:1592} INFO - Exporting the following env vars:
AIRFLOW_CTX_DAG_OWNER=***
AIRFLOW_CTX_DAG_ID=user_processing
AIRFLOW_CTX_TASK_ID=store_user
AIRFLOW_CTX_EXECUTION_DATE=2025-02-04T06:43:50.293731+00:00
AIRFLOW_CTX_TRY_NUMBER=1
AIRFLOW_CTX_DAG_RUN_ID=manual__2025-02-04T06:43:50.293731+00:00
[2025-02-04T06:44:07.430+0000] {taskinstance.py:1851} ERROR - Task failed with exception
Traceback (most recent call last):
  File "/home/airflow/.local/lib/python3.7/site-packages/airflow/operators/python.py", line 175, in execute
    return_value = self.execute_callable()
  File "/home/airflow/.local/lib/python3.7/site-packages/airflow/operators/python.py", line 193, in execute_callable
    return self.python_callable(*self.op_args, **self.op_kwargs)
  File "/opt/airflow/dags/user_processing.py", line 29, in _store_user
    hook = postgresHook(postgres_conn_id='postgres')  # Hook is an Extracting Tool
NameError: name 'postgresHook' is not defined
[2025-02-04T06:44:07.450+0000] {taskinstance.py:1406} INFO - Marking task as FAILED. dag_id=user_processing, task_id=store_user, execution_date=20250204T064350, start_date=20250204T064407, end_date=20250204T064407
[2025-02-04T06:44:07.475+0000] {standard_task_runner.py:105} ERROR - Failed to execute job 21 for task store_user (name 'postgresHook' is not defined; 7089)
[2025-02-04T06:44:07.501+0000] {local_task_job.py:164} INFO - Task exited with return code 1
[2025-02-04T06:44:07.533+0000] {local_task_job.py:273} INFO - 0 downstream tasks scheduled from follow-on schedule check
