[2025-02-09T03:54:06.133+0000] {taskinstance.py:1165} INFO - Dependencies all met for <TaskInstance: user_processing.store_user scheduled__2025-02-08T00:00:00+00:00 [queued]>
[2025-02-09T03:54:06.160+0000] {taskinstance.py:1165} INFO - Dependencies all met for <TaskInstance: user_processing.store_user scheduled__2025-02-08T00:00:00+00:00 [queued]>
[2025-02-09T03:54:06.160+0000] {taskinstance.py:1362} INFO - 
--------------------------------------------------------------------------------
[2025-02-09T03:54:06.161+0000] {taskinstance.py:1363} INFO - Starting attempt 1 of 1
[2025-02-09T03:54:06.162+0000] {taskinstance.py:1364} INFO - 
--------------------------------------------------------------------------------
[2025-02-09T03:54:06.198+0000] {taskinstance.py:1383} INFO - Executing <Task(PythonOperator): store_user> on 2025-02-08 00:00:00+00:00
[2025-02-09T03:54:06.206+0000] {standard_task_runner.py:55} INFO - Started process 127 to run task
[2025-02-09T03:54:06.213+0000] {standard_task_runner.py:82} INFO - Running: ['***', 'tasks', 'run', 'user_processing', 'store_user', 'scheduled__2025-02-08T00:00:00+00:00', '--job-id', '33', '--raw', '--subdir', 'DAGS_FOLDER/user_processing.py', '--cfg-path', '/tmp/tmpjrn5hsgz']
[2025-02-09T03:54:06.218+0000] {standard_task_runner.py:83} INFO - Job 33: Subtask store_user
[2025-02-09T03:54:06.474+0000] {task_command.py:376} INFO - Running <TaskInstance: user_processing.store_user scheduled__2025-02-08T00:00:00+00:00 [running]> on host fb1f760c5ca3
[2025-02-09T03:54:07.039+0000] {taskinstance.py:1592} INFO - Exporting the following env vars:
AIRFLOW_CTX_DAG_OWNER=***
AIRFLOW_CTX_DAG_ID=user_processing
AIRFLOW_CTX_TASK_ID=store_user
AIRFLOW_CTX_EXECUTION_DATE=2025-02-08T00:00:00+00:00
AIRFLOW_CTX_TRY_NUMBER=1
AIRFLOW_CTX_DAG_RUN_ID=scheduled__2025-02-08T00:00:00+00:00
[2025-02-09T03:54:07.044+0000] {taskinstance.py:1851} ERROR - Task failed with exception
Traceback (most recent call last):
  File "/home/airflow/.local/lib/python3.7/site-packages/airflow/operators/python.py", line 175, in execute
    return_value = self.execute_callable()
  File "/home/airflow/.local/lib/python3.7/site-packages/airflow/operators/python.py", line 193, in execute_callable
    return self.python_callable(*self.op_args, **self.op_kwargs)
  File "/opt/airflow/dags/user_processing.py", line 29, in _store_user
    hook = postgresHook(postgres_conn_id='postgres')  # Hook is an Extracting Tool
NameError: name 'postgresHook' is not defined
[2025-02-09T03:54:07.080+0000] {taskinstance.py:1406} INFO - Marking task as FAILED. dag_id=user_processing, task_id=store_user, execution_date=20250208T000000, start_date=20250209T035406, end_date=20250209T035407
[2025-02-09T03:54:07.145+0000] {standard_task_runner.py:105} ERROR - Failed to execute job 33 for task store_user (name 'postgresHook' is not defined; 127)
[2025-02-09T03:54:07.237+0000] {local_task_job.py:164} INFO - Task exited with return code 1
[2025-02-09T03:54:07.276+0000] {local_task_job.py:273} INFO - 0 downstream tasks scheduled from follow-on schedule check
